Workbook
Name ExternalData_1: 'Индекс с Дивидендами'!$A$1:$J$905
Name ExternalData_2: 'Все_дивиденды_xlsx'!$A$1:$C$649

Sheet Дивиденды
A1: Дивиденды эмитентов РФ с 2019 года
A3: Эмитент | B3: Тикер | C3: 2019 | D3: 2020 | E3: 2021 | F3: 2022 | G3: 2023 | H3: 2024 | I3: 2025
A4: "МОСКОВСКИЙ КРЕДИТНЫЙ БАНК" (ПАО) | B4: CBOM | C4: 0.11 | D4: - | E4: - | F4: - | G4: - | H4: - | I4: -
A5: Акционерная компания "АЛРОСА" (ПАО) | B5: ALRS | C5: 7.95 | D5: 2.63 | E5: 18.33 | F5: - | G5: 3.77 | H5: 4.51 | I5: -
A6: Банк ВТБ (ПАО) | B6: VTBR | C6: 0.00128 | D6: 0.00077 | E6: 0.0014 | I6: 25.58
A7: Международная Компания ПАО "МД Медикал Груп Инвестментс" | B7: MDMG | E7: 37 | F7: 8.55 | H7: 183 | I7: 64
A8: Международная Компания ПАО Юнайтед Медикал Груп | B8: GEMC | E8: 109.74
A9: Международная компания ПАО "ВК" | B9: VKCO | C9: - | D9: - | E9: - | F9: - | G9: - | H9: - | I9: -
A10: Международная компания ПАО "Озон" | B10: OZON | C10: - | D10: - | E10: - | F10: - | G10: - | H10: - | I10: 143.55
A11: Международная компания ПАО "Лента" | B11: LENT | C11: - | D11: - | E11: - | F11: - | G11: - | H11: - | I11: -
A12: Международная компания ПАО "Объединённая Компания "РУСАЛ"" | B12: RUAL | C12: - | D12: - | E12: - | F12: 1.21 | G12: - | H12: - | I12: -
A13: Международная компания ПАО "Т-Технологии" | B13: T | C13: 32.18 | D13: 59.86 | E13: 18.39 | H13: 92.5 | I13: 100
A14: Международная компания ПАО "Хэдхантер" | B14: HEAD | C14: 23.37 | D14: 39.15 | E14: 40.04 | F14: 54.81 | H14: 907 | I14: 233
A15: Международная компания ПАО "Циан" | B15: CNRU | C15: - | D15: - | E15: - | F15: - | G15: - | H15: - | I15: 104
A16: Международная компания ПАО "ЭН+ ГРУП" | B16: ENPG | C16: - | D16: - | E16: - | F16: - | G16: - | H16: - | I16: -
A17: Международная компания ПАО "ЯНДЕКС" | B17: YDEX | C17: - | D17: - | E17: - | F17: - | G17: - | H17: 80 | I17: 160
A18: ПАО "БАНК "САНКТ-ПЕТЕРБУРГ" | B18: BSPB | C18: 3.71 | D18: 3.33 | E18: 4.56 | F18: 11.81 | G18: 40.24 | H18: 50.63 | I18: 29.72
A19: ПАО "ИНАРКТИКА" | B19: AQUA | C19: - | D19: 5 | E19: 17 | F19: 38 | G19: 45 | H19: 50 | I19: 10
A20: ПАО "Акционерная финансовая корпорация "Система" | B20: AFKS | C20: 0.11 | D20: 0.13 | E20: 0.31 | F20: - | G20: 0.41 | H20: 0.52 | I20: -
A21: ПАО "Аэрофлот – российские авиалинии" | B21: AFLT | C21: 2.69 | D21: - | E21: - | F21: - | G21: - | H21: - | I21: 5.27
A22: ПАО "ВИ.ру" | B22: VSEH | C22: - | D22: - | E22: - | F22: - | G22: - | H22: - | I22: 1
A23: ПАО "Газпром" | B23: GAZP | C23: 16.61 | D23: 15.24 | E23: 12.55 | F23: 51.03 | G23: - | H23: - | I23: -
A24: ПАО "Горно-металлургическая компания "Норильский никель" | B24: GMKN | C24: 22.81 | D24: 11.8 | E24: 10.21 | F24: 26.89 | G24: 9.15 | H24: - | I24: -
A25: ПАО "Группа "Русагро" | B25: RAGR | C25: 37.69 | D25: 38.19 | E25: 144.1 | F25: - | G25: - | H25: - | I25: -
A26: ПАО "Группа ЛСР" | B26: LSRG | C26: 78 | D26: 50 | E26: 39 | G26: 78 | H26: 100 | I26: 78
A27: ПАО "Группа Позитив" | B27: POSI | C27: - | D27: - | E27: - | F27: 19.56 | G27: 72.61 | H27: 99.19 | I27: -
A28: ПАО "Группа Ренессанс Страхование" | B28: RENI | C28: - | D28: - | E28: - | F28: - | G28: 7.7 | H28: 5.9 | I28: 10.5
A29: ПАО "ДОМ.РФ" | B29: DOMRF | C29: - | D29: - | E29: - | F29: - | G29: - | H29: - | I29: -
A30: ПАО "ЕвроТранс" | B30: EUTR | C30: - | D30: - | E30: - | F30: - | G30: 8.88 | H30: 23.54 | I30: 31.85
A31: ПАО "Интер РАО ЕЭС" | B31: IRAO | C31: 0.17 | D31: 0.2 | E31: 0.18 | F31: 0.24 | G31: 0.28 | H31: 0.33 | I31: 0.35
A32: ПАО "Корпоративный центр ИКС 5" | B32: X5 | C32: 92.06 | D32: 184.11 | E32: 184.14 | F32: - | G32: - | H32: - | I32: 648
A33: ПАО "Лизинговая компания "Европлан" | B33: LEAS | C33: - | D33: - | E33: - | F33: - | G33: - | H33: 75 | I33: 87
A34: ПАО "М.видео" | B34: MVID | C34: 33.37 | D34: 30 | E34: 73 | F34: - | G34: - | H34: - | I34: -
A35: ПАО "МТС-Банк" | B35: MBNK | C35: - | D35: - | E35: - | F35: - | G35: - | H35: - | I35: 89.31
A36: ПАО "Магнитогорский металлургический комбинат" | B36: MAGN | C36: 166.78 | D36: 304.19 | E36: 784.99 | F36: - | G36: - | H36: 824.26 | I36: -
A37: ПАО "Мечел" | B37: MTLR | C37: - | D37: - | E37: - | F37: - | G37: - | H37: - | I37: -
A38: ПАО "Мечел" | B38: MTLRP | C38: 18.21 | D38: 3.48 | E38: 1.17 | F38: - | G38: - | H38: - | I38: -
A39: ПАО "Мобильные ТелеСистемы" | B39: MTSS | C39: 28.66 | D39: 42.75 | E39: 37.06 | F39: 33.85 | G39: 34.29 | H39: 35 | I39: 35
A40: ПАО "Московская Биржа ММВБ-РТС" | B40: MOEX | C40: 7.7 | D40: 7.93 | E40: 9.45 | G40: 4.84 | H40: 17.35 | I40: 26.11
A41: ПАО "Нефтяная компания "ЛУКОЙЛ" | B41: LKOH | C41: 347 | D41: 396 | E41: 553 | F41: 793 | G41: 885 | H41: 1012 | I41: 938
...

Sheet Все_дивиденды_xlsx
A1: Год | B1: Ticker | C1: Dividend
A2: 2001 | B2: AFLT | C2: 0.03
A3: 2001 | B3: LKOH | C3: 8
A4: 2001 | B4: MSNG | C4: 0.007667
A5: 2001 | B5: RTKM | C5: 0.1634
A6: 2001 | B6: SBER | C6: 0.0378
A7: 2002 | B7: AFLT | C7: 0.06
A8: 2002 | B8: GMKN | C8: 23
A9: 2002 | B9: LKOH | C9: 15
A10: 2002 | B10: MSNG | C10: 0.01837
A11: 2002 | B11: RTKM | C11: 0.2144961
A12: 2002 | B12: RTKMP | C12: 0.9195237
A13: 2002 | B13: SBER | C13: 0.0525
... A648: 2025 | B648: YDEX | C648: 160

Sheet Индекс с Дивидендами
A1: Год | B1: Код инструмента | C1: Цена, RUB | D1: Эфф. кол-во | E1: Капитализация, RUB | F1: FF | G1: Wi | H1: Кап. в индексе, RUB | I1: Вес, % | J1: Dividend | K1: Див. Доходность
A2: 2025 | B2: AFKS | C2: 13.34 | D2: 1910700000 | E2: 128731000000 | F2: 0.33 | G2: 0.6 | H2: 25488738000 | I2: 0.35 | K2: ='Индекс с Дивидендами'!$J2/'Индекс с Дивидендами'!$C2 -> 0
A3: 2025 | B3: VTBR | C3: 72.25 | D3: 3310209141 | E3: 4.7832522e+11 | F3: 0.5 | G3: 1 | H3: 2.3916261e+11 | I3: 3.3 | J3: 25.58 | K3: ='Индекс с Дивидендами'!$J3/'Индекс с Дивидендами'!$C3 -> 0.35404844
A4: 2025 | B4: ALRS | C4: 41.42 | D4: 0 | E4: 3.0505688e+11 | F4: 0.34 | G4: 0.4 | H4: 4.1487735e+10 | I4: 0.57 | K4: ='Индекс с Дивидендами'!$J4/'Индекс с Дивидендами'!$C4 -> 0
A5: 2025 | B5: X5 | C5: 3011 | D5: 0 | E5: 817705917592 | F5: 0.29 | G5: 1 | H5: 2.3713472e+11 | I5: 3.27 | J5: 648 | K5: ='Индекс с Дивидендами'!$J5/'Индекс с Дивидендами'!$C5 -> 0.21521089
A6: 2025 | B6: CBOM | C6: 6.09 | D6: 0 | E6: 2.0358693e+11 | F6: 0.22 | G6: 0.7 | H6: 3.1352388e+10 | I6: 0.43 | K6: ='Индекс с Дивидендами'!$J6/'Индекс с Дивидендами'!$C6 -> 0
A7: 2025 | B7: CHMF | C7: 966.6 | D7: 0 | E7: 809738856756 | F7: 0.23 | G7: 0.4 | H7: 7.4495975e+10 | I7: 1.03 | K7: ='Индекс с Дивидендами'!$J7/'Индекс с Дивидендами'!$C7 -> 0
A8: 2025 | B8: SNGSP | C8: 41.8 | D8: 0 | E8: 321943526223 | F8: 0.73 | G8: 0.5 | H8: 1.1750939e+11 | I8: 1.62 | J8: 8.5 | K8: ='Индекс с Дивидендами'!$J8/'Индекс с Дивидендами'!$C8 -> 0.20334928
A9: 2025 | B9: DOMRF | C9: 1858.2 | D9: 0 | E9: 3.3426922e+11 | F9: 0.1 | G9: 1 | H9: 3.3426922e+10 | I9: 0.46 | K9: ='Индекс с Дивидендами'!$J9/'Индекс с Дивидендами'!$C9 -> 0
A10: 2025 | B10: ENPG | C10: 454.2 | D10: 0 | E10: 2.9016517e+11 | F10: 0.14 | G10: 0.6 | H10: 2.4373874e+10 | I10: 0.34 | K10: ='Индекс с Дивидендами'!$J10/'Индекс с Дивидендами'!$C10 -> 0
A11: 2025 | B11: FLOT | C11: 75.88 | D11: 0 | E11: 1.8021454e+11 | F11: 0.16 | G11: 0.7 | H11: 2.0184028e+10 | I11: 0.28 | K11: ='Индекс с Дивидендами'!$J11/'Индекс с Дивидендами'!$C11 -> 0
A12: 2025 | B12: GAZP | C12: 125.57 | D12: 0 | E12: 2972683014853 | F12: 0.47 | G12: 0.5 | H12: 6.9858051e+11 | I12: 9.65 | K12: ='Индекс с Дивидендами'!$J12/'Индекс с Дивидендами'!$C12 -> 0
A13: 2025 | B13: GMKN | C13: 149.02 | D13: 0 | E13: 2277970342094 | F13: 0.33 | G13: 0.4 | H13: 3.0069209e+11 | I13: 4.15 | K13: ='Индекс с Дивидендами'!$J13/'Индекс с Дивидендами'!$C13 -> 0
A14: 2025 | B14: CNRU | C14: 606.8 | D14: 0 | E14: 47130453332 | F14: 0.37 | G14: 1 | H14: 1.7438268e+10 | I14: 0.24 | J14: 104 | K14: ='Индекс с Дивидендами'!$J14/'Индекс с Дивидендами'!$C14 -> 0.1713909
A15: 2025 | B15: MTSS | C15: 213.65 | D15: 0 | E15: 4.2695422e+11 | F15: 0.41 | G15: 0.4 | H15: 7.0020493e+10 | I15: 0.97 | J15: 35 | K15: ='Индекс с Дивидендами'!$J15/'Индекс с Дивидендами'!$C15 -> 0.16381933
A16: 2025 | B16: MOEX | C16: 173.88 | D16: 0 | E16: 3.9582069e+11 | F16: 0.65 | G16: 0.3 | H16: 7.7185034e+10 | I16: 1.07 | J16: 26.11 | K16: ='Индекс с Дивидендами'!$J16/'Индекс с Дивидендами'!$C16 -> 0.15016103
A17: 2025 | B17: MAGN | C17: 28.63 | D17: 1340919600 | E17: 319921067900 | F17: 0.2 | G17: 0.6 | H17: 38390528148 | I17: 0.53 | K17: ='Индекс с Дивидендами'!$J17/'Индекс с Дивидендами'!$C17 -> 0
A18: 2025 | B18: BSPB | C18: 309 | D18: 0 | E18: 137618872989 | F18: 0.28 | G18: 0.6 | H18: 2.3119971e+10 | I18: 0.32 | J18: 46.33 | K18: ='Индекс с Дивидендами'!$J18/'Индекс с Дивидендами'!$C18 -> 0.14993528
A19: 2025 | B19: TRNFP | C19: 1381.4 | D19: 23012150 | E19: 214790432500 | F19: 0.37 | G19: 0.4 | H19: 31788984010 | I19: 0.44 | J19: 198.25 | K19: ='Индекс с Дивидендами'!$J19/'Индекс с Дивидендами'!$C19 -> 0.14351383
A20: 2025 | B20: MSNG | C20: 2.0885 | D20: 7154884746 | E20: 8.3016538e+10 | F20: 0.2 | G20: 0.9 | H20: 1.4942977e+10 | I20: 0.21 | K20: ='Индекс с Дивидендами'!$J20/'Индекс с Дивидендами'!$C20 -> 0
A21: 2025 | B21: TATNP | C21: 540.7 | D21: 103255950 | E21: 79757845950 | F21: 1 | G21: 0.7 | H21: 55830492165 | I21: 0.77 | J21: 74.85 | K21: ='Индекс с Дивидендами'!$J21/'Индекс с Дивидендами'!$C21 -> 0.13843166
A22: 2025 | B22: NLMK | C22: 106.6 | D22: 0 | E22: 638878023784 | F22: 0.21 | G22: 0.5 | H22: 6.7082192e+10 | I22: 0.93 | K22: ='Индекс с Дивидендами'!$J22/'Индекс с Дивидендами'!$C22 -> 0
A23: 2025 | B23: TATN | C23: 581 | D23: 0 | E23: 1265819296700 | F23: 0.32 | G23: 0.8 | H23: 3.2404974e+11 | I23: 4.47 | J23: 74.85 | K23: ='Индекс с Дивидендами'!$J23/'Индекс с Дивидендами'!$C23 -> 0.1288296
A24: 2025 | B24: ROSN | C24: 408.65 | D24: 0 | E24: 4.3309454e+12 | F24: 0.11 | G24: 0.4 | H24: 1.905616e+11 | I24: 2.63 | J24: 51.15 | K24: ='Индекс с Дивидендами'!$J24/'Индекс с Дивидендами'!$C24 -> 0.12516824
A25: 2025 | B25: SBERP | C25: 299.74 | D25: 557346800 | E25: 299740000000 | F25: 1 | G25: 0.5573468 | H25: 167059129832 | I25: 2.31 | J25: 34.84 | K25: ='Индекс с Дивидендами'!$J25/'Индекс с Дивидендами'!$C25 -> 0.11623407
A26: 2025 | B26: PIKK | C26: 490 | D26: 0 | E26: 323643698560 | F26: 0.21 | G26: 1 | H26: 6.7965177e+10 | I26: 0.94 | K26: ='Индекс с Дивидендами'!$J26/'Индекс с Дивидендами'!$C26 -> 0
A27: 2025 | B27: SBER | C27: 300.28 | D27: 0 | E27: 6482128745440 | F27: 0.48 | G27: 0.2786734 | H27: 8.6707049e+11 | I27: 11.97 | J27: 34.84 | K27: ='Индекс с Дивидендами'!$J27/'Индекс с Дивидендами'!$C27 -> 0.11602504
A28: 2025 | B28: POSI | C28: 997 | D28: 17091360 | E28: 71000358000 | F28: 0.24 | G28: 1 | H28: 17040085920 | I28: 0.24 | K28: ='Индекс с Дивидендами'!$J28/'Индекс с Дивидендами'!$C28 -> 0
A29: 2025 | B29: IRAO | C29: 3.1125 | D29: 23385600000 | E29: 324945000000 | F29: 0.32 | G29: 0.7 | H29: 72787680000 | I29: 1 | J29: 0.3538 | K29: ='Индекс с Дивидендами'!$J29/'Индекс с Дивидендами'!$C29 -> 0.11367068
A30: 2025 | B30: RENI | C30: 95.9 | D30: 0 | E30: 53411771602 | F30: 0.3 | G30: 0.9 | H30: 1.4421178e+10 | I30: 0.2 | J30: 10.5 | K30: ='Индекс с Дивидендами'!$J30/'Индекс с Дивидендами'!$C30 -> 0.10948905
A31: 2025 | B31: LKOH | C31: 5880.5 | D31: 0 | E31: 4074397113441 | F31: 0.55 | G31: 0.49729 | H31: 1.1143863e+12 | I31: 15.39 | J31: 541 | K31: ='Индекс с Дивидендами'!$J31/'Индекс с Дивидендами'!$C31 -> 0.09199898
A32: 2025 | B32: RUAL | C32: 33.91 | D32: 0 | E32: 5.1519513e+11 | F32: 0.18 | G32: 0.7 | H32: 6.4914587e+10 | I32: 0.9 | K32: ='Индекс с Дивидендами'!$J32/'Индекс с Дивидендами'!$C32 -> 0
A33: 2025 | B33: AFLT | C33: 57.7 | D33: 795154243 | E33: 2.29402e+11 | F33: 0.25 | G33: 0.8 | H33: 4.58804e+10 | I33: 0.63 | J33: 5.27 | K33: ='Индекс с Дивидендами'!$J33/'Индекс с Дивидендами'!$C33 -> 0.091334489
A34: 2025 | B34: HEAD | C34: 2907 | D34: 0 | E34: 137166556626 | F34: 0.42 | G34: 1 | H34: 5.7609954e+10 | I34: 0.8 | J34: 233 | K34: ='Индекс с Дивидендами'!$J34/'Индекс с Дивидендами'!$C34 -> 0.080151359
A35: 2025 | B35: PLZL | C35: 2401.6 | D35: 0 | E35: 3.2678427e+12 | F35: 0.22 | G35: 0.4 | H35: 2.8757016e+11 | I35: 3.97 | J35: 179.85 | K35: ='Индекс с Дивидендами'!$J35/'Индекс с Дивидендами'!$C35 -> 0.074887575
A36: 2025 | B36: PHOR | C36: 6371 | D36: 6734000 | E36: 825044500000 | F36: 0.26 | G36: 0.2 | H36: 42902314000 | I36: 0.59 | J36: 459 | K36: ='Индекс с Дивидендами'!$J36/'Индекс с Дивидендами'!$C36 -> 0.072045205
A37: 2025 | B37: NVTK | C37: 1188 | D37: 255049704 | E37: 3607131528000 | F37: 0.21 | G37: 0.4 | H37: 302999048352 | I37: 4.18 | J37: 82.15 | K37: ='Индекс с Дивидендами'!$J37/'Индекс с Дивидендами'!$C37 -> 0.069149832
A38: 2025 | B38: MDMG | C38: 1497.8 | D38: 0 | E38: 112522239978 | F38: 0.27 | G38: 0.9 | H38: 2.7342904e+10 | I38: 0.38 | J38: 64 | K38: ='Индекс с Дивидендами'!$J38/'Индекс с Дивидендами'!$C38 -> 0.042729336
A39: 2025 | B39: RTKM | C39: 63.99 | D39: 0 | E39: 2.1007904e+11 | F39: 0.29 | G39: 0.7 | H39: 4.2646045e+10 | I39: 0.59 | J39: 2.71 | K39: ='Индекс с Дивидендами'!$J39/'Индекс с Дивидендами'!$C39 -> 0.042350367
A40: 2025 | B40: SNGS | C40: 21.79 | D40: 0 | E40: 7.7846942e+11 | F40: 0.25 | G40: 0.7 | H40: 1.3623215e+11 | I40: 1.88 | J40: 0.9 | K40: ='Индекс с Дивидендами'!$J40/'Индекс с Дивидендами'!$C40 -> 0.04130335
...

Sheet Лист1
A1: Год | B1: Код инструмента | C1: Цена, RUB | D1: Эфф. кол-во | E1: Капитализация, RUB | F1: FF | G1: Wi | H1: Кап. в индексе, RUB | I1: Вес, %
A2: 2025 | B2: AFKS | C2: 13.34 | D2: 1910700000 | E2: 128731000000 | F2: 0.33 | G2: 0.6 | H2: 25488738000 | I2: 0.35
A3: 2025 | B3: AFLT | C3: 57.7 | D3: 795154243 | E3: 2.29402e+11 | F3: 0.25 | G3: 0.8 | H3: 4.58804e+10 | I3: 0.63
A4: 2025 | B4: ALRS | C4: 41.42 | D4: 0 | E4: 3.0505688e+11 | F4: 0.34 | G4: 0.4 | H4: 4.1487735e+10 | I4: 0.57
A5: 2025 | B5: BSPB | C5: 309 | D5: 0 | E5: 137618872989 | F5: 0.28 | G5: 0.6 | H5: 2.3119971e+10 | I5: 0.32
A6: 2025 | B6: CBOM | C6: 6.09 | D6: 0 | E6: 2.0358693e+11 | F6: 0.22 | G6: 0.7 | H6: 3.1352388e+10 | I6: 0.43
A7: 2025 | B7: CHMF | C7: 966.6 | D7: 0 | E7: 809738856756 | F7: 0.23 | G7: 0.4 | H7: 7.4495975e+10 | I7: 1.03
A8: 2025 | B8: CNRU | C8: 606.8 | D8: 0 | E8: 47130453332 | F8: 0.37 | G8: 1 | H8: 1.7438268e+10 | I8: 0.24
A9: 2025 | B9: DOMRF | C9: 1858.2 | D9: 0 | E9: 3.3426922e+11 | F9: 0.1 | G9: 1 | H9: 3.3426922e+10 | I9: 0.46
A10: 2025 | B10: ENPG | C10: 454.2 | D10: 0 | E10: 2.9016517e+11 | F10: 0.14 | G10: 0.6 | H10: 2.4373874e+10 | I10: 0.34
A11: 2025 | B11: FLOT | C11: 75.88 | D11: 0 | E11: 1.8021454e+11 | F11: 0.16 | G11: 0.7 | H11: 2.0184028e+10 | I11: 0.28
A12: 2025 | B12: GAZP | C12: 125.57 | D12: 0 | E12: 2972683014853 | F12: 0.47 | G12: 0.5 | H12: 6.9858051e+11 | I12: 9.65
A13: 2025 | B13: GMKN | C13: 149.02 | D13: 0 | E13: 2277970342094 | F13: 0.33 | G13: 0.4 | H13: 3.0069209e+11 | I13: 4.15
... A905: 2001 | B905: YUKO | C905: 155.888 | D905: 0 | E905: 0 | F905: 0 | G905: 0 | H905: 0 | I905: 5.2
